nohup: ignoring input
 * Serving Flask app 'anonym_backend'
 * Debug mode: on
[31m[1mWARNING: This is a development server. Do not use it in a production deployment. Use a production WSGI server instead.[0m
 * Running on all addresses (0.0.0.0)
 * Running on http://127.0.0.1:2053
 * Running on http://10.0.23.29:2053
[33mPress CTRL+C to quit[0m
 * Restarting with stat
 * Debugger is active!
 * Debugger PIN: 114-014-020
141.143.213.54 - - [24/May/2024 12:35:55] "POST /anonymise HTTP/1.1" 200 -
141.143.213.37 - - [24/May/2024 12:36:04] "OPTIONS /anonymise HTTP/1.1" 200 -
141.143.213.37 - - [24/May/2024 12:36:04] "POST /anonymise HTTP/1.1" 200 -
141.143.213.37 - - [24/May/2024 12:36:44] "OPTIONS /anonymise HTTP/1.1" 200 -
141.143.213.37 - - [24/May/2024 12:36:44] "POST /anonymise HTTP/1.1" 200 -
 * Detected change in '/home/ubuntu/backend/anonym_backend.py', reloading
 * Restarting with stat
 * Debugger is active!
 * Debugger PIN: 114-014-020
141.143.213.54 - - [24/May/2024 12:38:43] "[35m[1mPOST /anonymise HTTP/1.1[0m" 500 -
Traceback (most recent call last):
  File "/home/ubuntu/anaconda3/envs/IKARD/lib/python3.10/site-packages/flask/app.py", line 2213, in __call__
    return self.wsgi_app(environ, start_response)
  File "/home/ubuntu/anaconda3/envs/IKARD/lib/python3.10/site-packages/flask/app.py", line 2193, in wsgi_app
    response = self.handle_exception(e)
  File "/home/ubuntu/anaconda3/envs/IKARD/lib/python3.10/site-packages/flask_cors/extension.py", line 178, in wrapped_function
    return cors_after_request(app.make_response(f(*args, **kwargs)))
  File "/home/ubuntu/anaconda3/envs/IKARD/lib/python3.10/site-packages/flask/app.py", line 2190, in wsgi_app
    response = self.full_dispatch_request()
  File "/home/ubuntu/anaconda3/envs/IKARD/lib/python3.10/site-packages/flask/app.py", line 1486, in full_dispatch_request
    rv = self.handle_user_exception(e)
  File "/home/ubuntu/anaconda3/envs/IKARD/lib/python3.10/site-packages/flask_cors/extension.py", line 178, in wrapped_function
    return cors_after_request(app.make_response(f(*args, **kwargs)))
  File "/home/ubuntu/anaconda3/envs/IKARD/lib/python3.10/site-packages/flask/app.py", line 1484, in full_dispatch_request
    rv = self.dispatch_request()
  File "/home/ubuntu/anaconda3/envs/IKARD/lib/python3.10/site-packages/flask/app.py", line 1469, in dispatch_request
    return self.ensure_sync(self.view_functions[rule.endpoint])(**view_args)
  File "/home/ubuntu/backend/anonym_backend.py", line 48, in anonymise
    header, image_data, extension = get_base64_info(b64_image, extension)
UnboundLocalError: local variable 'extension' referenced before assignment
 * Detected change in '/home/ubuntu/backend/anonym_backend.py', reloading
 * Restarting with stat
 * Debugger is active!
 * Debugger PIN: 114-014-020
141.143.213.54 - - [24/May/2024 12:39:06] "[35m[1mPOST /anonymise HTTP/1.1[0m" 500 -
Traceback (most recent call last):
  File "/home/ubuntu/anaconda3/envs/IKARD/lib/python3.10/site-packages/flask/app.py", line 2213, in __call__
    return self.wsgi_app(environ, start_response)
  File "/home/ubuntu/anaconda3/envs/IKARD/lib/python3.10/site-packages/flask/app.py", line 2193, in wsgi_app
    response = self.handle_exception(e)
  File "/home/ubuntu/anaconda3/envs/IKARD/lib/python3.10/site-packages/flask_cors/extension.py", line 178, in wrapped_function
    return cors_after_request(app.make_response(f(*args, **kwargs)))
  File "/home/ubuntu/anaconda3/envs/IKARD/lib/python3.10/site-packages/flask/app.py", line 2190, in wsgi_app
    response = self.full_dispatch_request()
  File "/home/ubuntu/anaconda3/envs/IKARD/lib/python3.10/site-packages/flask/app.py", line 1486, in full_dispatch_request
    rv = self.handle_user_exception(e)
  File "/home/ubuntu/anaconda3/envs/IKARD/lib/python3.10/site-packages/flask_cors/extension.py", line 178, in wrapped_function
    return cors_after_request(app.make_response(f(*args, **kwargs)))
  File "/home/ubuntu/anaconda3/envs/IKARD/lib/python3.10/site-packages/flask/app.py", line 1484, in full_dispatch_request
    rv = self.dispatch_request()
  File "/home/ubuntu/anaconda3/envs/IKARD/lib/python3.10/site-packages/flask/app.py", line 1469, in dispatch_request
    return self.ensure_sync(self.view_functions[rule.endpoint])(**view_args)
  File "/home/ubuntu/backend/anonym_backend.py", line 48, in anonymise
    writeLog("logs.txt", f"header: {header}")
UnboundLocalError: local variable 'header' referenced before assignment
 * Detected change in '/home/ubuntu/backend/anonym_backend.py', reloading
 * Restarting with stat
 * Debugger is active!
 * Debugger PIN: 114-014-020
141.143.213.54 - - [24/May/2024 12:39:30] "[35m[1mPOST /anonymise HTTP/1.1[0m" 500 -
Traceback (most recent call last):
  File "/home/ubuntu/anaconda3/envs/IKARD/lib/python3.10/site-packages/flask/app.py", line 2213, in __call__
    return self.wsgi_app(environ, start_response)
  File "/home/ubuntu/anaconda3/envs/IKARD/lib/python3.10/site-packages/flask/app.py", line 2193, in wsgi_app
    response = self.handle_exception(e)
  File "/home/ubuntu/anaconda3/envs/IKARD/lib/python3.10/site-packages/flask_cors/extension.py", line 178, in wrapped_function
    return cors_after_request(app.make_response(f(*args, **kwargs)))
  File "/home/ubuntu/anaconda3/envs/IKARD/lib/python3.10/site-packages/flask/app.py", line 2190, in wsgi_app
    response = self.full_dispatch_request()
  File "/home/ubuntu/anaconda3/envs/IKARD/lib/python3.10/site-packages/flask/app.py", line 1486, in full_dispatch_request
    rv = self.handle_user_exception(e)
  File "/home/ubuntu/anaconda3/envs/IKARD/lib/python3.10/site-packages/flask_cors/extension.py", line 178, in wrapped_function
    return cors_after_request(app.make_response(f(*args, **kwargs)))
  File "/home/ubuntu/anaconda3/envs/IKARD/lib/python3.10/site-packages/flask/app.py", line 1484, in full_dispatch_request
    rv = self.dispatch_request()
  File "/home/ubuntu/anaconda3/envs/IKARD/lib/python3.10/site-packages/flask/app.py", line 1469, in dispatch_request
    return self.ensure_sync(self.view_functions[rule.endpoint])(**view_args)
  File "/home/ubuntu/backend/anonym_backend.py", line 48, in anonymise
    header, image_data, extension = get_base64_info(b64_image, extension)
UnboundLocalError: local variable 'extension' referenced before assignment
 * Detected change in '/home/ubuntu/backend/anonym_backend.py', reloading
 * Restarting with stat
 * Debugger is active!
 * Debugger PIN: 114-014-020
141.143.213.54 - - [24/May/2024 12:40:02] "POST /anonymise HTTP/1.1" 200 -
167.71.201.139 - - [24/May/2024 16:11:58] code 400, message Bad request version ('À\x13À')
167.71.201.139 - - [24/May/2024 16:11:58] "[35m[1m\x16\x03\x01\x01\x07\x01\x00\x01\x03\x03\x03)ÙcLÃsÓ@½R$,\x0d*\x7f#3\x18\x1eâ¾Ñ\x075ýu\x13zô,T\x8f ·\x09=_o%ÌK\x81åu\x0d¥V8\x97)À\x90\x0d»°\x0dÇ\x83¢æÎ1@ @\x00&À+À/À,À0Ì©Ì¨À\x09À\x13À[0m" HTTPStatus.BAD_REQUEST -
192.99.7.195 - - [24/May/2024 16:32:13] code 400, message Bad request version ('À\x13À')
192.99.7.195 - - [24/May/2024 16:32:13] "[35m[1m\x16\x03\x01\x01\x07\x01\x00\x01\x03\x03\x03á k¤Ã{\x99\x86>º\x09\x14\x02ë)j¯\x15Ã\x9fªB\x0bØ÷"ô\x7f|ªt\x06 uOå\x8f\x83æ¡ \x0c¦0\x07dá¸\x81nïa\x16$Ï\x88\x83)· ZaÓ®Ó\x00&À+À/À,À0Ì©Ì¨À\x09À\x13À[0m" HTTPStatus.BAD_REQUEST -
167.71.201.103 - - [25/May/2024 00:11:39] "[33mGET /cdn-cgi/trace HTTP/1.1[0m" 404 -
167.71.201.103 - - [25/May/2024 00:11:45] code 400, message Bad request version ('À\x13À')
167.71.201.103 - - [25/May/2024 00:11:45] "[35m[1m\x16\x03\x01\x01\x07\x01\x00\x01\x03\x03\x03-$á\x0dü\x13\x8d\x03`\x9a\x7f-Vú97\x09\x08\x82piæm.ï)æÇ\x06äFw B\x1e§a¤Å\x02\x05ôéñâ\x89ÈìÈtû:\x06ò\x1e\x9ekp\x0bÅ¨â\x17Èó\x00&À+À/À,À0Ì©Ì¨À\x09À\x13À[0m" HTTPStatus.BAD_REQUEST -
35.203.210.195 - - [25/May/2024 01:20:35] code 400, message Bad request version ('À\x13À')
35.203.210.195 - - [25/May/2024 01:20:35] "[35m[1m\x16\x03\x01\x00î\x01\x00\x00ê\x03\x03U}Áe\x1eÊê0ä\x87kY¬¦­\x93 eDPÓ\x17x\x00\x0cC\x86r¨1:° ¿^^\\\x01\x884ÄT¦ÛÂ:7(rULÜ\x14Ré\x00\x0d+2íª©^Êk\x00&À+À/À,À0Ì©Ì¨À\x09À\x13À[0m" HTTPStatus.BAD_REQUEST -
35.203.210.195 - - [25/May/2024 01:20:35] code 400, message Bad request version ('eà\x90È\x9bá\x1a')
35.203.210.195 - - [25/May/2024 01:20:35] "[35m[1m\x16\x03\x01\x00Ê\x01\x00\x00Æ\x03\x03õ\x90\x85Rx¥Z\x1ceà\x90È\x9bá\x1a[0m" HTTPStatus.BAD_REQUEST -
199.45.154.78 - - [25/May/2024 04:11:13] code 400, message Bad request version ('À\x14À')
199.45.154.78 - - [25/May/2024 04:11:13] "[35m[1m\x16\x03\x01\x00î\x01\x00\x00ê\x03\x03Õ\x04\x03\x01\x93üÑÝ\x06\x18Iz¡\x0dA®\x14Á\x16rf\x1cwªÖ\x12\x9fD:T\x1d\x05 }HWôÉÃ3\x09%zÂV¦1$U@¿\x99Ô>\x04ûk\x11Õ\x1e\x10ÈÜö«\x00&Ì¨Ì©À/À0À+À,À\x13À\x09À\x14À[0m" HTTPStatus.BAD_REQUEST -
199.45.154.78 - - [25/May/2024 04:11:17] "[33mGET / HTTP/1.1[0m" 404 -
199.45.154.78 - - [25/May/2024 04:11:29] "[33mGET / HTTP/1.1[0m" 404 -
199.45.154.78 - - [25/May/2024 04:11:30] code 505, message Invalid HTTP version (2.0)
199.45.154.78 - - [25/May/2024 04:11:30] "[35m[1mPRI * HTTP/2.0[0m" HTTPStatus.HTTP_VERSION_NOT_SUPPORTED -
167.94.138.43 - - [25/May/2024 06:04:17] code 400, message Bad request version ('À\x14À')
167.94.138.43 - - [25/May/2024 06:04:17] "[35m[1m\x16\x03\x01\x00î\x01\x00\x00ê\x03\x03\x97b^OÀÇ¬àá\x1eKí`\x98Xâ®M}q\x0fðêeXÞ5\x9c½\x1fcR øØ\x9f\x11, °\x87Kû©\x1e\x8e\x16WÇ\x19\x81\x15îr7`vÂ+\x92*Ì\x8c_é\x00&Ì¨Ì©À/À0À+À,À\x13À\x09À\x14À[0m" HTTPStatus.BAD_REQUEST -
167.94.138.43 - - [25/May/2024 06:04:24] "[33mGET / HTTP/1.1[0m" 404 -
167.94.138.43 - - [25/May/2024 06:04:30] "[33mGET / HTTP/1.1[0m" 404 -
167.94.138.43 - - [25/May/2024 06:04:35] code 505, message Invalid HTTP version (2.0)
167.94.138.43 - - [25/May/2024 06:04:35] "[35m[1mPRI * HTTP/2.0[0m" HTTPStatus.HTTP_VERSION_NOT_SUPPORTED -
139.59.101.104 - - [25/May/2024 09:05:28] code 400, message Bad request version ('À\x13À')
139.59.101.104 - - [25/May/2024 09:05:28] "[35m[1m\x16\x03\x01\x01\x07\x01\x00\x01\x03\x03\x03=\x89%k/\x10s£µQ¯\x00ùsë<xCJO\x96m<\x90\x1c«\x08ì\x86¢¯! ¸]k8\x0dá\x14ÿ\x18}\x02T2\x1dq\x87\x09»æ*\x1c_\x1cêÎ`a|æ\x8d¼\x92\x00&À+À/À,À0Ì©Ì¨À\x09À\x13À[0m" HTTPStatus.BAD_REQUEST -
35.203.210.182 - - [25/May/2024 13:04:43] code 400, message Bad request version ('À\x13À')
35.203.210.182 - - [25/May/2024 13:04:43] "[35m[1m\x16\x03\x01\x00î\x01\x00\x00ê\x03\x03Tg$å\x97\x1f\x92\x13Eh.l\x93UJöîÒ«\x04\x94_vWb\\Ù_k;é\x12 Í!+ri,Ø¾5;åè\x90UíÎÒ¤0Õ·&*z"&õ\x99+\x9dÝv\x00&À+À/À,À0Ì©Ì¨À\x09À\x13À[0m" HTTPStatus.BAD_REQUEST -
35.203.210.182 - - [25/May/2024 13:04:43] code 400, message Bad request syntax ('\x16\x03\x01\x00Ê\x01\x00\x00Æ\x03\x03¸\x07ÈÔÿÏ¬;HÆé`\x8e§$u\x82h"\x12ÞJ\x82ê\x07éW')
35.203.210.182 - - [25/May/2024 13:04:43] "[35m[1m\x16\x03\x01\x00Ê\x01\x00\x00Æ\x03\x03¸\x07ÈÔÿÏ¬;HÆé`\x8e§$u\x82h"\x12ÞJ\x82ê\x07éW[0m" HTTPStatus.BAD_REQUEST -
192.99.7.195 - - [25/May/2024 16:26:46] code 400, message Bad request version ('À\x13À')
192.99.7.195 - - [25/May/2024 16:26:46] "[35m[1m\x16\x03\x01\x01\x07\x01\x00\x01\x03\x03\x03\x93£Aï&&\x8c´iÎq\x13\x0dÝ¤\x0b\x95C®=¢\x0d\x08X`G¹ÍË\x85 C \x82\x1cÆÀAqñ\x94~÷°r\x0bÄÄpÏêW\x17\x1aú4e\x0f¡>\x0d\x85\x15¸\x98\x00&À+À/À,À0Ì©Ì¨À\x09À\x13À[0m" HTTPStatus.BAD_REQUEST -
35.203.210.113 - - [25/May/2024 21:50:28] code 400, message Bad request version ('À\x13À')
35.203.210.113 - - [25/May/2024 21:50:28] "[35m[1m\x16\x03\x01\x00î\x01\x00\x00ê\x03\x03¢\x048JºÔí\x07è\x11´ë\x1e\x84þâD\x0c}k°±·6whØË¸n1á cJ·\x03tÌò\x96íÍÃ\x87ÊÝ\x9b¾i\x81´~\x81&\x03ÎáÓÖ\x11µè=Á\x00&À+À/À,À0Ì©Ì¨À\x09À\x13À[0m" HTTPStatus.BAD_REQUEST -
35.203.210.113 - - [25/May/2024 21:50:28] code 400, message Bad request version ('À(À$À\x14À')
35.203.210.113 - - [25/May/2024 21:50:28] "[35m[1m\x16\x03\x01\x00Ê\x01\x00\x00Æ\x03\x03äÎP©'T\x0cîI\x96ÍØ¨Ù\x08|\x0cp´»Ó{.×\x96\x12øÚ¥\x00¼Q\x00\x00hÌ\x14Ì\x13À/À+À0À,À\x11À\x07À'À#À\x13À\x09À(À$À\x14À[0m" HTTPStatus.BAD_REQUEST -
185.242.226.27 - - [25/May/2024 21:54:21] "[33mGET / HTTP/1.1[0m" 404 -
167.71.197.10 - - [26/May/2024 00:11:36] "[33mGET /cdn-cgi/trace HTTP/1.1[0m" 404 -
167.71.197.10 - - [26/May/2024 00:11:44] code 400, message Bad request version ('\x86!Ù\x9f\x82¡ó\x18}°ñ®\x14\x8cTþ\xad%ÒX¹\x8c\x8b\x88\x9bÊ\x10ú')
167.71.197.10 - - [26/May/2024 00:11:44] "[35m[1m\x16\x03\x01\x01\x07\x01\x00\x01\x03\x03\x03@ª¢O\x0by^\x02\x0c\x18¼\x97?äi¡{DÍ\x9c\x85ú-}Ù\x1f_\x93$xqÓ \x86!Ù\x9f\x82¡ó\x18}°ñ®\x14\x8cTþ­%ÒX¹\x8c\x8b\x88\x9bÊ\x10ú[0m" HTTPStatus.BAD_REQUEST -
45.79.181.251 - - [26/May/2024 02:53:06] code 400, message Bad request version ('À\x14À')
45.79.181.251 - - [26/May/2024 02:53:06] "[35m[1m\x16\x03\x01\x00\x85\x01\x00\x00\x81\x03\x038²Cç\x00ßÖaïG\x067\x16¾\x92]h½Ö\x0fT}\x9fÙO÷Ò_\x1d\x98ýá\x00\x00 À/À0À+À,Ì¨Ì©À\x13À\x09À\x14À[0m" HTTPStatus.BAD_REQUEST -
162.142.125.11 - - [26/May/2024 09:32:09] code 400, message Bad request version ('À\x14À')
162.142.125.11 - - [26/May/2024 09:32:09] "[35m[1m\x16\x03\x01\x00î\x01\x00\x00ê\x03\x03ÇmwI\x9aÊ\x12G«F-çY¦Ü\x0cÓÉ.\x14\x09kºcÚ\x88È"ï\x1cb\x10 ýnt\x10VÎOB+\x96WGÃ¬\x96"V\x9a\x80\x91\x96\x88Ý®Ëß\x93´³È!\x94\x00&Ì¨Ì©À/À0À+À,À\x13À\x09À\x14À[0m" HTTPStatus.BAD_REQUEST -
162.142.125.11 - - [26/May/2024 09:32:13] "[33mGET / HTTP/1.1[0m" 404 -
162.142.125.11 - - [26/May/2024 09:32:16] "[33mGET / HTTP/1.1[0m" 404 -
162.142.125.11 - - [26/May/2024 09:32:16] code 505, message Invalid HTTP version (2.0)
162.142.125.11 - - [26/May/2024 09:32:16] "[35m[1mPRI * HTTP/2.0[0m" HTTPStatus.HTTP_VERSION_NOT_SUPPORTED -
167.94.145.104 - - [26/May/2024 12:00:46] code 400, message Bad request version ('À\x14À')
167.94.145.104 - - [26/May/2024 12:00:46] "[35m[1m\x16\x03\x01\x00î\x01\x00\x00ê\x03\x03à\x86IH\x05\x8aï\x05\x1aC\x9a\x8a\x09lVKFyl\x18¢ÚR¦x\x81X¿¶\x0e°À Ü¶\x03\x03å\x14ÜÂ\x87ó\x17\x93)ù&\x9aÆð\x04Ñã\\Fûßh\x00×'\x12]\\\x00&Ì¨Ì©À/À0À+À,À\x13À\x09À\x14À[0m" HTTPStatus.BAD_REQUEST -
167.94.145.104 - - [26/May/2024 12:00:49] "[33mGET / HTTP/1.1[0m" 404 -
167.94.145.104 - - [26/May/2024 12:00:52] "[33mGET / HTTP/1.1[0m" 404 -
167.94.145.104 - - [26/May/2024 12:00:52] code 505, message Invalid HTTP version (2.0)
167.94.145.104 - - [26/May/2024 12:00:52] "[35m[1mPRI * HTTP/2.0[0m" HTTPStatus.HTTP_VERSION_NOT_SUPPORTED -
84.54.51.13 - - [26/May/2024 14:58:02] "[33mPOST /login HTTP/1.1[0m" 404 -
167.71.201.139 - - [26/May/2024 16:12:36] "[33mGET /cdn-cgi/trace HTTP/1.1[0m" 404 -
192.99.7.195 - - [26/May/2024 16:33:00] code 400, message Bad request version ('À\x13À')
192.99.7.195 - - [26/May/2024 16:33:00] "[35m[1m\x16\x03\x01\x01\x07\x01\x00\x01\x03\x03\x03Rû%\x94ÔÈ\x9a²L<\x1dQyxæwf:",\x9dÄ\x1cÍ£NÎº"$\x01V µ°\x07Æ\x89\x0bì)ñV\x85õ=¤ODM1ë®\x8aU<õ\x1a\x13ª\x88\x1b]\x1f\x9a\x00&À+À/À,À0Ì©Ì¨À\x09À\x13À[0m" HTTPStatus.BAD_REQUEST -
84.54.51.43 - - [26/May/2024 20:46:53] "[33mGET / HTTP/1.1[0m" 404 -
162.216.149.134 - - [26/May/2024 21:35:28] code 400, message Bad request version ('À\x13À')
162.216.149.134 - - [26/May/2024 21:35:28] "[35m[1m\x16\x03\x01\x00î\x01\x00\x00ê\x03\x03\x06¾h\x09ýÞn û\x10ì\x8e.èQÎ Ãô\x9c\x89\x833BKî\x02Îß[ü0 â\x92r5R\x0dÔ«ÿ¬ß\x12\x1ejÆk{NXñª\x81`¯ð-\x90õ\x96\x9eÎm\x00&À+À/À,À0Ì©Ì¨À\x09À\x13À[0m" HTTPStatus.BAD_REQUEST -
162.216.149.134 - - [26/May/2024 21:35:28] code 400, message Bad request version ('À(À$À\x14À')
162.216.149.134 - - [26/May/2024 21:35:28] "[35m[1m\x16\x03\x01\x00Ê\x01\x00\x00Æ\x03\x03©Ñ #Zµ\x98\x83S\x17l\x9c¼WR\x85eØ\x9f_\x0cCñ[\x92e\x14#¯ýqã\x00\x00hÌ\x14Ì\x13À/À+À0À,À\x11À\x07À'À#À\x13À\x09À(À$À\x14À[0m" HTTPStatus.BAD_REQUEST -
157.230.37.129 - - [27/May/2024 00:11:37] "[33mGET /cdn-cgi/trace HTTP/1.1[0m" 404 -
157.230.37.129 - - [27/May/2024 00:11:44] code 400, message Bad request version ('À\x13À')
157.230.37.129 - - [27/May/2024 00:11:44] "[35m[1m\x16\x03\x01\x01\x07\x01\x00\x01\x03\x03\x03%Ë\x13ë \x1eDhD\x16S\x92g\x06ÐÂøÜûÅ\x96Û=Ñ|þ\x96ÙÇß(\x1d êù¢w\x8cþÏ\x94\x80\x88:]Á&÷êk`%àQ\x87d·ßX\x12\x01ò\x1bÅ·\x00&À+À/À,À0Ì©Ì¨À\x09À\x13À[0m" HTTPStatus.BAD_REQUEST -
84.54.51.43 - - [27/May/2024 00:51:23] "[33mGET / HTTP/1.1[0m" 404 -
172.104.11.51 - - [27/May/2024 02:48:05] code 400, message Bad request version ('À\x14À')
172.104.11.51 - - [27/May/2024 02:48:05] "[35m[1m\x16\x03\x01\x00\x85\x01\x00\x00\x81\x03\x03¤ár\x01Ü\x05ý¯hàSX$B:ð1\x0e\x81"8#lS@Àõøvºäl\x00\x00 À/À0À+À,Ì¨Ì©À\x13À\x09À\x14À[0m" HTTPStatus.BAD_REQUEST -
 * Detected change in '/home/ubuntu/backend/anonym_backend.py', reloading
 * Restarting with stat
 * Debugger is active!
 * Debugger PIN: 114-014-020
 * Detected change in '/home/ubuntu/backend/anonym_backend.py', reloading
 * Restarting with stat
 * Debugger is active!
 * Debugger PIN: 114-014-020
141.143.213.49 - - [27/May/2024 03:41:32] "OPTIONS /anonymise HTTP/1.1" 200 -
141.143.213.49 - - [27/May/2024 03:41:32] "[35m[1mPOST /anonymise HTTP/1.1[0m" 500 -
Traceback (most recent call last):
  File "/home/ubuntu/anaconda3/envs/IKARD/lib/python3.10/site-packages/flask/app.py", line 2213, in __call__
    return self.wsgi_app(environ, start_response)
  File "/home/ubuntu/anaconda3/envs/IKARD/lib/python3.10/site-packages/flask/app.py", line 2193, in wsgi_app
    response = self.handle_exception(e)
  File "/home/ubuntu/anaconda3/envs/IKARD/lib/python3.10/site-packages/flask_cors/extension.py", line 178, in wrapped_function
    return cors_after_request(app.make_response(f(*args, **kwargs)))
  File "/home/ubuntu/anaconda3/envs/IKARD/lib/python3.10/site-packages/flask/app.py", line 2190, in wsgi_app
    response = self.full_dispatch_request()
  File "/home/ubuntu/anaconda3/envs/IKARD/lib/python3.10/site-packages/flask/app.py", line 1486, in full_dispatch_request
    rv = self.handle_user_exception(e)
  File "/home/ubuntu/anaconda3/envs/IKARD/lib/python3.10/site-packages/flask_cors/extension.py", line 178, in wrapped_function
    return cors_after_request(app.make_response(f(*args, **kwargs)))
  File "/home/ubuntu/anaconda3/envs/IKARD/lib/python3.10/site-packages/flask/app.py", line 1484, in full_dispatch_request
    rv = self.dispatch_request()
  File "/home/ubuntu/anaconda3/envs/IKARD/lib/python3.10/site-packages/flask/app.py", line 1469, in dispatch_request
    return self.ensure_sync(self.view_functions[rule.endpoint])(**view_args)
  File "/home/ubuntu/backend/anonym_backend.py", line 283, in anonymise
    res = get_anonym_image(image_data, extension)
  File "/home/ubuntu/backend/anonym_backend.py", line 32, in get_anonym_image
    config = oci.config.from_file('/home/ubuntu/.oci/config', CONFIG_PROFILE)
NameError: name 'oci' is not defined
 * Detected change in '/home/ubuntu/backend/anonym_backend.py', reloading
 * Restarting with stat
 * Debugger is active!
 * Debugger PIN: 114-014-020
 * Detected change in '/home/ubuntu/backend/anonym_backend.py', reloading
 * Restarting with stat
 * Debugger is active!
 * Debugger PIN: 114-014-020
141.143.213.49 - - [27/May/2024 03:45:17] "OPTIONS /anonymise HTTP/1.1" 200 -
141.143.213.49 - - [27/May/2024 03:45:18] "[35m[1mPOST /anonymise HTTP/1.1[0m" 500 -
Traceback (most recent call last):
  File "/home/ubuntu/anaconda3/envs/IKARD/lib/python3.10/site-packages/flask/app.py", line 2213, in __call__
    return self.wsgi_app(environ, start_response)
  File "/home/ubuntu/anaconda3/envs/IKARD/lib/python3.10/site-packages/flask/app.py", line 2193, in wsgi_app
    response = self.handle_exception(e)
  File "/home/ubuntu/anaconda3/envs/IKARD/lib/python3.10/site-packages/flask_cors/extension.py", line 178, in wrapped_function
    return cors_after_request(app.make_response(f(*args, **kwargs)))
  File "/home/ubuntu/anaconda3/envs/IKARD/lib/python3.10/site-packages/flask/app.py", line 2190, in wsgi_app
    response = self.full_dispatch_request()
  File "/home/ubuntu/anaconda3/envs/IKARD/lib/python3.10/site-packages/flask/app.py", line 1486, in full_dispatch_request
    rv = self.handle_user_exception(e)
  File "/home/ubuntu/anaconda3/envs/IKARD/lib/python3.10/site-packages/flask_cors/extension.py", line 178, in wrapped_function
    return cors_after_request(app.make_response(f(*args, **kwargs)))
  File "/home/ubuntu/anaconda3/envs/IKARD/lib/python3.10/site-packages/flask/app.py", line 1484, in full_dispatch_request
    rv = self.dispatch_request()
  File "/home/ubuntu/anaconda3/envs/IKARD/lib/python3.10/site-packages/flask/app.py", line 1469, in dispatch_request
    return self.ensure_sync(self.view_functions[rule.endpoint])(**view_args)
  File "/home/ubuntu/backend/anonym_backend.py", line 283, in anonymise
    writeLog("going to anonymizer...")
TypeError: writeLog() missing 1 required positional argument: 'obj'
141.143.213.49 - - [27/May/2024 03:46:28] "OPTIONS /anonymise HTTP/1.1" 200 -
141.143.213.49 - - [27/May/2024 03:46:28] "[35m[1mPOST /anonymise HTTP/1.1[0m" 500 -
Traceback (most recent call last):
  File "/home/ubuntu/anaconda3/envs/IKARD/lib/python3.10/site-packages/flask/app.py", line 2213, in __call__
    return self.wsgi_app(environ, start_response)
  File "/home/ubuntu/anaconda3/envs/IKARD/lib/python3.10/site-packages/flask/app.py", line 2193, in wsgi_app
    response = self.handle_exception(e)
  File "/home/ubuntu/anaconda3/envs/IKARD/lib/python3.10/site-packages/flask_cors/extension.py", line 178, in wrapped_function
    return cors_after_request(app.make_response(f(*args, **kwargs)))
  File "/home/ubuntu/anaconda3/envs/IKARD/lib/python3.10/site-packages/flask/app.py", line 2190, in wsgi_app
    response = self.full_dispatch_request()
  File "/home/ubuntu/anaconda3/envs/IKARD/lib/python3.10/site-packages/flask/app.py", line 1486, in full_dispatch_request
    rv = self.handle_user_exception(e)
  File "/home/ubuntu/anaconda3/envs/IKARD/lib/python3.10/site-packages/flask_cors/extension.py", line 178, in wrapped_function
    return cors_after_request(app.make_response(f(*args, **kwargs)))
  File "/home/ubuntu/anaconda3/envs/IKARD/lib/python3.10/site-packages/flask/app.py", line 1484, in full_dispatch_request
    rv = self.dispatch_request()
  File "/home/ubuntu/anaconda3/envs/IKARD/lib/python3.10/site-packages/flask/app.py", line 1469, in dispatch_request
    return self.ensure_sync(self.view_functions[rule.endpoint])(**view_args)
  File "/home/ubuntu/backend/anonym_backend.py", line 283, in anonymise
    writeLog("going to anonymizer...")
TypeError: writeLog() missing 1 required positional argument: 'obj'
 * Detected change in '/home/ubuntu/backend/anonym_backend.py', reloading
 * Restarting with stat
 * Debugger is active!
 * Debugger PIN: 114-014-020
141.143.213.49 - - [27/May/2024 03:47:11] "OPTIONS /anonymise HTTP/1.1" 200 -
141.143.213.49 - - [27/May/2024 03:47:11] "[35m[1mPOST /anonymise HTTP/1.1[0m" 500 -
Traceback (most recent call last):
  File "/home/ubuntu/anaconda3/envs/IKARD/lib/python3.10/site-packages/flask/app.py", line 2213, in __call__
    return self.wsgi_app(environ, start_response)
  File "/home/ubuntu/anaconda3/envs/IKARD/lib/python3.10/site-packages/flask/app.py", line 2193, in wsgi_app
    response = self.handle_exception(e)
  File "/home/ubuntu/anaconda3/envs/IKARD/lib/python3.10/site-packages/flask_cors/extension.py", line 178, in wrapped_function
    return cors_after_request(app.make_response(f(*args, **kwargs)))
  File "/home/ubuntu/anaconda3/envs/IKARD/lib/python3.10/site-packages/flask/app.py", line 2190, in wsgi_app
    response = self.full_dispatch_request()
  File "/home/ubuntu/anaconda3/envs/IKARD/lib/python3.10/site-packages/flask/app.py", line 1486, in full_dispatch_request
    rv = self.handle_user_exception(e)
  File "/home/ubuntu/anaconda3/envs/IKARD/lib/python3.10/site-packages/flask_cors/extension.py", line 178, in wrapped_function
    return cors_after_request(app.make_response(f(*args, **kwargs)))
  File "/home/ubuntu/anaconda3/envs/IKARD/lib/python3.10/site-packages/flask/app.py", line 1484, in full_dispatch_request
    rv = self.dispatch_request()
  File "/home/ubuntu/anaconda3/envs/IKARD/lib/python3.10/site-packages/flask/app.py", line 1469, in dispatch_request
    return self.ensure_sync(self.view_functions[rule.endpoint])(**view_args)
  File "/home/ubuntu/backend/anonym_backend.py", line 284, in anonymise
    res = get_anonym_image(image_data, extension)
  File "/home/ubuntu/backend/anonym_backend.py", line 32, in get_anonym_image
    config = oci.config.from_file('/home/ubuntu/.oci/config', CONFIG_PROFILE)
NameError: name 'oci' is not defined
141.143.213.49 - - [27/May/2024 04:04:01] "OPTIONS /anonymise HTTP/1.1" 200 -
141.143.213.49 - - [27/May/2024 04:04:01] "[35m[1mPOST /anonymise HTTP/1.1[0m" 500 -
Traceback (most recent call last):
  File "/home/ubuntu/anaconda3/envs/IKARD/lib/python3.10/site-packages/flask/app.py", line 2213, in __call__
    return self.wsgi_app(environ, start_response)
  File "/home/ubuntu/anaconda3/envs/IKARD/lib/python3.10/site-packages/flask/app.py", line 2193, in wsgi_app
    response = self.handle_exception(e)
  File "/home/ubuntu/anaconda3/envs/IKARD/lib/python3.10/site-packages/flask_cors/extension.py", line 178, in wrapped_function
    return cors_after_request(app.make_response(f(*args, **kwargs)))
  File "/home/ubuntu/anaconda3/envs/IKARD/lib/python3.10/site-packages/flask/app.py", line 2190, in wsgi_app
    response = self.full_dispatch_request()
  File "/home/ubuntu/anaconda3/envs/IKARD/lib/python3.10/site-packages/flask/app.py", line 1486, in full_dispatch_request
    rv = self.handle_user_exception(e)
  File "/home/ubuntu/anaconda3/envs/IKARD/lib/python3.10/site-packages/flask_cors/extension.py", line 178, in wrapped_function
    return cors_after_request(app.make_response(f(*args, **kwargs)))
  File "/home/ubuntu/anaconda3/envs/IKARD/lib/python3.10/site-packages/flask/app.py", line 1484, in full_dispatch_request
    rv = self.dispatch_request()
  File "/home/ubuntu/anaconda3/envs/IKARD/lib/python3.10/site-packages/flask/app.py", line 1469, in dispatch_request
    return self.ensure_sync(self.view_functions[rule.endpoint])(**view_args)
  File "/home/ubuntu/backend/anonym_backend.py", line 284, in anonymise
    res = get_anonym_image(image_data, extension)
  File "/home/ubuntu/backend/anonym_backend.py", line 32, in get_anonym_image
    config = oci.config.from_file('/home/ubuntu/.oci/config', CONFIG_PROFILE)
NameError: name 'oci' is not defined
141.143.213.49 - - [27/May/2024 04:04:09] "OPTIONS /anonymise HTTP/1.1" 200 -
141.143.213.49 - - [27/May/2024 04:04:09] "[35m[1mPOST /anonymise HTTP/1.1[0m" 500 -
Traceback (most recent call last):
  File "/home/ubuntu/anaconda3/envs/IKARD/lib/python3.10/site-packages/flask/app.py", line 2213, in __call__
    return self.wsgi_app(environ, start_response)
  File "/home/ubuntu/anaconda3/envs/IKARD/lib/python3.10/site-packages/flask/app.py", line 2193, in wsgi_app
    response = self.handle_exception(e)
  File "/home/ubuntu/anaconda3/envs/IKARD/lib/python3.10/site-packages/flask_cors/extension.py", line 178, in wrapped_function
    return cors_after_request(app.make_response(f(*args, **kwargs)))
  File "/home/ubuntu/anaconda3/envs/IKARD/lib/python3.10/site-packages/flask/app.py", line 2190, in wsgi_app
    response = self.full_dispatch_request()
  File "/home/ubuntu/anaconda3/envs/IKARD/lib/python3.10/site-packages/flask/app.py", line 1486, in full_dispatch_request
    rv = self.handle_user_exception(e)
  File "/home/ubuntu/anaconda3/envs/IKARD/lib/python3.10/site-packages/flask_cors/extension.py", line 178, in wrapped_function
    return cors_after_request(app.make_response(f(*args, **kwargs)))
  File "/home/ubuntu/anaconda3/envs/IKARD/lib/python3.10/site-packages/flask/app.py", line 1484, in full_dispatch_request
    rv = self.dispatch_request()
  File "/home/ubuntu/anaconda3/envs/IKARD/lib/python3.10/site-packages/flask/app.py", line 1469, in dispatch_request
    return self.ensure_sync(self.view_functions[rule.endpoint])(**view_args)
  File "/home/ubuntu/backend/anonym_backend.py", line 284, in anonymise
    res = get_anonym_image(image_data, extension)
  File "/home/ubuntu/backend/anonym_backend.py", line 32, in get_anonym_image
    config = oci.config.from_file('/home/ubuntu/.oci/config', CONFIG_PROFILE)
NameError: name 'oci' is not defined
